Workbook

Sheet Comparação
A1: Comparação: modelo atual x modelo melhorado
A2: Verde = ligação com as outras abas. Variação = melhorado / atual - 1. Tempo em minutos, vazão em clientes por hora.
A4: Fila | B4: Índice | C4: Atual (sem. 1) | D4: Melhorado (sem. 1) | E4: Variação | F4: Atual (média 5 sem.) | G4: Melhorado (média 5 sem.) | H4: Variação
A5: Q1 (N1 - Triagem) | B5: Perdas | C5: =Atual_Q1!$B$8 -> 0 | D5: =Melhorado_Q1!$B$8 -> 0 | E5: =IF(C5=0,"-",D5/C5-1) -> - | F5: =Sementes!$D$10 -> 0 | G5: =Sementes!$D$34 -> 0 | H5: =IF(F5=0,"-",G5/F5-1) -> -
A6: Q1 (N1 - Triagem) | B6: População (N) | C6: =Atual_Q1!$D$16 -> 1.4156813 | D6: =Melhorado_Q1!$D$16 -> 1.3948851 | E6: =IF(C6=0,"-",D6/C6-1) -> -0.014689863 | F6: =Sementes!$E$10 -> 1.4113398 | G6: =Sementes!$E$34 -> 1.4007249 | H6: =IF(F6=0,"-",G6/F6-1) -> -0.0075211473
A7: Q1 (N1 - Triagem) | B7: Vazão (D) | C7: =Atual_Q1!$E$16 -> 10.417063 | D7: =Melhorado_Q1!$E$16 -> 10.313983 | E7: =IF(C7=0,"-",D7/C7-1) -> -0.0098953401 | F7: =Sementes!$F$10 -> 10.393216 | G7: =Sementes!$F$34 -> 10.337424 | H7: =IF(F7=0,"-",G7/F7-1) -> -0.0053681144
A8: Q1 (N1 - Triagem) | B8: Utilização (U) | C8: =Atual_Q1!$F$16 -> 0.69447087 | D8: =Melhorado_Q1!$F$16 -> 0.68759884 | E8: =IF(C8=0,"-",D8/C8-1) -> -0.0098953401 | F8: =Sementes!$G$10 -> 0.69288104 | G8: =Sementes!$G$34 -> 0.68916158 | H8: =IF(F8=0,"-",G8/F8-1) -> -0.0053681144
A9: Q1 (N1 - Triagem) | B9: Tempo de resposta (W) | C9: =Atual_Q1!$B$19 -> 8.1540137 | D9: =Melhorado_Q1!$B$19 -> 8.1145284 | E9: =IF(C9=0,"-",D9/C9-1) -> -0.00484244 | F9: =Sementes!$H$10 -> 8.1476503 | G9: =Sementes!$H$34 -> 8.1299932 | H9: =IF(F9=0,"-",G9/F9-1) -> -0.0021671421
A11: Q2 (N2 - Especialista) | B11: Perdas | C11: =Atual_Q2!$B$8 -> 2057 | D11: =Melhorado_Q2!$B$8 -> 19 | E11: =IF(C11=0,"-",D11/C11-1) -> -0.99076325 | F11: =Sementes!$D$18 -> 2249.4 | G11: =Sementes!$D$42 -> 30 | H11: =IF(F11=0,"-",G11/F11-1) -> -0.98666311
A12: Q2 (N2 - Especialista) | B12: População (N) | C12: =Atual_Q2!$D$22 -> 8.1739699 | D12: =Melhorado_Q2!$D$22 -> 2.608666 | E12: =IF(C12=0,"-",D12/C12-1) -> -0.68085691 | F12: =Sementes!$E$18 -> 8.3387711 | G12: =Sementes!$E$42 -> 2.8421001 | H12: =IF(F12=0,"-",G12/F12-1) -> -0.65917038
A13: Q2 (N2 - Especialista) | B13: Vazão (D) | C13: =Atual_Q2!$E$22 -> 3.991643 | D13: =Melhorado_Q2!$E$22 -> 3.1912601 | E13: =IF(C13=0,"-",D13/C13-1) -> -0.20051466 | F13: =Sementes!$F$18 -> 3.9948012 | G13: =Sementes!$F$42 -> 3.2827244 | H13: =IF(F13=0,"-",G13/F13-1) -> -0.17825087
A14: Q2 (N2 - Especialista) | B14: Utilização (U) | C14: =Atual_Q2!$F$22 -> 0.99791074 | D14: =Melhorado_Q2!$F$22 -> 0.79781501 | E14: =IF(C14=0,"-",D14/C14-1) -> -0.20051466 | F14: =Sementes!$G$18 -> 0.9987003 | G14: =Sementes!$G$42 -> 0.8206811 | H14: =IF(F14=0,"-",G14/F14-1) -> -0.17825087
A15: Q2 (N2 - Especialista) | B15: Tempo de resposta (W) | C15: =Atual_Q2!$B$25 -> 122.86625 | D15: =Melhorado_Q2!$B$25 -> 49.046446 | E15: =IF(C15=0,"-",D15/C15-1) -> -0.60081433 | F15: =Sementes!$H$18 -> 125.24316 | G15: =Sementes!$H$42 -> 51.918748 | H15: =IF(F15=0,"-",G15/F15-1) -> -0.58545642
A17: Q3 (N3 - Desenvolvimento) | B17: Perdas | C17: =Atual_Q3!$B$8 -> 79 | D17: =Melhorado_Q3!$B$8 -> 15 | E17: =IF(C17=0,"-",D17/C17-1) -> -0.81012658 | F17: =Sementes!$D$26 -> 124.6 | G17: =Sementes!$D$50 -> 28.6 | H17: =IF(F17=0,"-",G17/F17-1) -> -0.77046549
A18: Q3 (N3 - Desenvolvimento) | B18: População (N) | C18: =Atual_Q3!$D$17 -> 1.923261 | D18: =Melhorado_Q3!$D$17 -> 1.3047627 | E18: =IF(C18=0,"-",D18/C18-1) -> -0.32158833 | F18: =Sementes!$E$26 -> 2.1320812 | G18: =Sementes!$E$50 -> 1.3886866 | H18: =IF(F18=0,"-",G18/F18-1) -> -0.34867086
A19: Q3 (N3 - Desenvolvimento) | B19: Vazão (D) | C19: =Atual_Q3!$E$17 -> 1.1183532 | D19: =Melhorado_Q3!$E$17 -> 0.95720479 | E19: =IF(C19=0,"-",D19/C19-1) -> -0.14409434 | F19: =Sementes!$F$26 -> 1.1533427 | G19: =Sementes!$F$50 -> 0.97415976 | H19: =IF(F19=0,"-",G19/F19-1) -> -0.1553597
A20: Q3 (N3 - Desenvolvimento) | B20: Utilização (U) | C20: =Atual_Q3!$F$17 -> 0.83876487 | D20: =Melhorado_Q3!$F$17 -> 0.71790359 | E20: =IF(C20=0,"-",D20/C20-1) -> -0.14409434 | F20: =Sementes!$G$26 -> 0.86500705 | G20: =Sementes!$G$50 -> 0.73061982 | H20: =IF(F20=0,"-",G20/F20-1) -> -0.1553597
A21: Q3 (N3 - Desenvolvimento) | B21: Tempo de resposta (W) | C21: =Atual_Q3!$B$20 -> 103.18356 | D21: =Melhorado_Q3!$B$20 -> 81.785803 | E21: =IF(C21=0,"-",D21/C21-1) -> -0.20737564 | F21: =Sementes!$H$26 -> 110.85857 | G21: =Sementes!$H$50 -> 85.502745 | H21: =IF(F21=0,"-",G21/F21-1) -> -0.22872229
A23: A vazão (D) do N2 e do N3 cai porque, com menos chamados escalando, chega menos trabalho a eles; não é perda de capacidade.

Sheet Parâmetros
A1: Parâmetros dos modelos (unidade de tempo: minutos)
A2: Azul = lido do .yml. MU é a taxa de atendimento de um servidor, em clientes por hora: 60 / tempo médio de atendimento.
A4: Modelo | B4: Fila | C4: Papel | D4: Kendall | E4: Servidores (C) | F4: Capacidade (K) | G4: Atend. mín | H4: Atend. máx | I4: Tempo médio | J4: MU (cl/h) | K4: Chegada mín | L4: Chegada máx | M4: 1ª chegada
A5: Atual | B5: Q1 | C5: N1 - Triagem | D5: G/G/2/∞ | E5: 2 | F5: ∞ | G5: 6 | H5: 10 | I5: =(G5+H5)/2 -> 8 | J5: =60/I5 -> 7.5 | K5: 4 | L5: 8 | M5: 6
A6: Atual | B6: Q2 | C6: N2 - Especialista | D6: G/G/2/10 | E6: 2 | F6: 10 | G6: 20 | H6: 40 | I6: =(G6+H6)/2 -> 30 | J6: =60/I6 -> 2
A7: Atual | B7: Q3 | C7: N3 - Desenvolvimento | D7: G/G/1/5 | E7: 1 | F7: 5 | G7: 30 | H7: 60 | I7: =(G7+H7)/2 -> 45 | J7: =60/I7 -> 1.3333333
A9: Melhorado | B9: Q1 | C9: N1 - Triagem | D9: G/G/2/∞ | E9: 2 | F9: ∞ | G9: 6 | H9: 10 | I9: =(G9+H9)/2 -> 8 | J9: =60/I9 -> 7.5 | K9: 4 | L9: 8 | M9: 6
A10: Melhorado | B10: Q2 | C10: N2 - Especialista | D10: G/G/2/10 | E10: 2 | F10: 10 | G10: 20 | H10: 40 | I10: =(G10+H10)/2 -> 30 | J10: =60/I10 -> 2
A11: Melhorado | B11: Q3 | C11: N3 - Desenvolvimento | D11: G/G/1/5 | E11: 1 | F11: 5 | G11: 30 | H11: 60 | I11: =(G11+H11)/2 -> 45 | J11: =60/I11 -> 1.3333333
A14: Roteamento entre as filas
A15: Origem | B15: Destino | C15: Prob. atual | D15: Prob. melhorado
A16: Q1 | B16: Q2 | C16: 0.45 | D16: 0.3
A17: Q1 | B17: sai da rede (resolvido) | C17: =1-SUM(C16) -> 0.55 | D17: =1-SUM(D16) -> 0.7
A18: Q2 | B18: Q3 | C18: 0.3 | D18: 0.3
A19: Q2 | B19: Q1 | C19: 0.1 | D19: 0.1
A20: Q2 | B20: sai da rede (resolvido) | C20: =1-SUM(C18:C19) -> 0.6 | D20: =1-SUM(D18:D19) -> 0.6
A21: Q3 | B21: Q2 | C21: 0.2 | D21: 0.2
A22: Q3 | B22: sai da rede (resolvido) | C22: =1-SUM(C21) -> 0.8 | D22: =1-SUM(D21) -> 0.8
A24: Amarelo = parâmetro alterado na melhoria.

Sheet Atual_Q1
A1: Atual - Q1 (N1 - Triagem)
A3: Kendall | B3: G/G/2/∞
A4: Servidores (C) | B4: =Parâmetros!$E$5 -> 2
A5: Capacidade (K) | B5: =Parâmetros!$F$5 -> ∞
A6: MU (clientes/h) | B6: =Parâmetros!$J$5 -> 7.5
A7: Tempo global (min) | B7: 146269.72
A8: Perdas | B8: 0
A10: i | B10: Tempo acumulado (min) | C10: Probabilidade | D10: N (clientes) | E10: D (cl/h) | F10: U
A11: 0 | B11: 1799.9511 | C11: =B11/$B$7 -> 0.012305699 | D11: =C11*A11 -> 0 | E11: =C11*MIN(A11,$B$4)*$B$6 -> 0 | F11: =C11*MIN(A11,$B$4)/$B$4 -> 0
A12: 1 | B12: 85779.417 | C12: =B12/$B$7 -> 0.58644686 | D12: =C12*A12 -> 0.58644686 | E12: =C12*MIN(A12,$B$4)*$B$6 -> 4.3983515 | F12: =C12*MIN(A12,$B$4)/$B$4 -> 0.29322343
A13: 2 | B13: 54849.145 | C13: =B13/$B$7 -> 0.37498634 | D13: =C13*A13 -> 0.74997267 | E13: =C13*MIN(A13,$B$4)*$B$6 -> 5.624795 | F13: =C13*MIN(A13,$B$4)/$B$4 -> 0.37498634
A14: 3 | B14: 3771.2276 | C14: =B14/$B$7 -> 0.025782695 | D14: =C14*A14 -> 0.077348086 | E14: =C14*MIN(A14,$B$4)*$B$6 -> 0.38674043 | F14: =C14*MIN(A14,$B$4)/$B$4 -> 0.025782695
A15: 4 | B15: 69.976637 | C15: =B15/$B$7 -> 0.00047840823 | D15: =C15*A15 -> 0.0019136329 | E15: =C15*MIN(A15,$B$4)*$B$6 -> 0.0071761235 | F15: =C15*MIN(A15,$B$4)/$B$4 -> 0.00047840823
A16: Total | B16: =SUM(B11:B15) -> 146269.72 | C16: =SUM(C11:C15) -> 1 | D16: =SUM(D11:D15) -> 1.4156813 | E16: =SUM(E11:E15) -> 10.417063 | F16: =SUM(F11:F15) -> 0.69447087
A18: W (horas) = N / D | B18: =D16/E16 -> 0.13590023
A19: W (minutos) | B19: =B18*60 -> 8.1540137
A21: Soma dos tempos = tempo global? | B21: =IF(ABS(B16-B7)<0.001,"OK","ERRO") -> OK

Sheet Atual_Q2
A1: Atual - Q2 (N2 - Especialista)
A3: Kendall | B3: G/G/2/10
A4: Servidores (C) | B4: =Parâmetros!$E$6 -> 2
A5: Capacidade (K) | B5: =Parâmetros!$F$6 -> 10
A6: MU (clientes/h) | B6: =Parâmetros!$J$6 -> 2
A7: Tempo global (min) | B7: 146269.72
A8: Perdas | B8: 2057
A10: i | B10: Tempo acumulado (min) | C10: Probabilidade | D10: N (clientes) | E10: D (cl/h) | F10: U
A11: 0 | B11: 68.935804 | C11: =B11/$B$7 -> 0.00047129239 | D11: =C11*A11 -> 0 | E11: =C11*MIN(A11,$B$4)*$B$6 -> 0 | F11: =C11*MIN(A11,$B$4)/$B$4 -> 0
A12: 1 | B12: 473.318 | C12: =B12/$B$7 -> 0.0032359261 | D12: =C12*A12 -> 0.0032359261 | E12: =C12*MIN(A12,$B$4)*$B$6 -> 0.0064718523 | F12: =C12*MIN(A12,$B$4)/$B$4 -> 0.0016179631
A13: 2 | B13: 998.02099 | C13: =B13/$B$7 -> 0.0068231552 | D13: =C13*A13 -> 0.01364631 | E13: =C13*MIN(A13,$B$4)*$B$6 -> 0.027292621 | F13: =C13*MIN(A13,$B$4)/$B$4 -> 0.0068231552
A14: 3 | B14: 1917.0967 | C14: =B14/$B$7 -> 0.013106586 | D14: =C14*A14 -> 0.039319758 | E14: =C14*MIN(A14,$B$4)*$B$6 -> 0.052426345 | F14: =C14*MIN(A14,$B$4)/$B$4 -> 0.013106586
A15: 4 | B15: 3102.7599 | C15: =B15/$B$7 -> 0.021212592 | D15: =C15*A15 -> 0.084850369 | E15: =C15*MIN(A15,$B$4)*$B$6 -> 0.084850369 | F15: =C15*MIN(A15,$B$4)/$B$4 -> 0.021212592
A16: 5 | B16: 5724.3166 | C16: =B16/$B$7 -> 0.03913535 | D16: =C16*A16 -> 0.19567675 | E16: =C16*MIN(A16,$B$4)*$B$6 -> 0.1565414 | F16: =C16*MIN(A16,$B$4)/$B$4 -> 0.03913535
A17: 6 | B17: 9481.779 | C17: =B17/$B$7 -> 0.064823937 | D17: =C17*A17 -> 0.38894362 | E17: =C17*MIN(A17,$B$4)*$B$6 -> 0.25929575 | F17: =C17*MIN(A17,$B$4)/$B$4 -> 0.064823937
A18: 7 | B18: 16807.021 | C18: =B18/$B$7 -> 0.11490431 | D18: =C18*A18 -> 0.80433018 | E18: =C18*MIN(A18,$B$4)*$B$6 -> 0.45961725 | F18: =C18*MIN(A18,$B$4)/$B$4 -> 0.11490431
A19: 8 | B19: 30899.15 | C19: =B19/$B$7 -> 0.21124776 | D19: =C19*A19 -> 1.6899821 | E19: =C19*MIN(A19,$B$4)*$B$6 -> 0.84499104 | F19: =C19*MIN(A19,$B$4)/$B$4 -> 0.21124776
A20: 9 | B20: 43355.221 | C20: =B20/$B$7 -> 0.296406 | D20: =C20*A20 -> 2.667654 | E20: =C20*MIN(A20,$B$4)*$B$6 -> 1.185624 | F20: =C20*MIN(A20,$B$4)/$B$4 -> 0.296406
A21: 10 | B21: 33442.098 | C21: =B21/$B$7 -> 0.22863309 | D21: =C21*A21 -> 2.2863309 | E21: =C21*MIN(A21,$B$4)*$B$6 -> 0.91453237 | F21: =C21*MIN(A21,$B$4)/$B$4 -> 0.22863309
A22: Total | B22: =SUM(B11:B21) -> 146269.72 | C22: =SUM(C11:C21) -> 1 | D22: =SUM(D11:D21) -> 8.1739699 | E22: =SUM(E11:E21) -> 3.991643 | F22: =SUM(F11:F21) -> 0.99791074
A24: W (horas) = N / D | B24: =D22/E22 -> 2.0477708
A25: W (minutos) | B25: =B24*60 -> 122.86625
A27: Soma dos tempos = tempo global? | B27: =IF(ABS(B22-B7)<0.001,"OK","ERRO") -> OK

Sheet Atual_Q3
A1: Atual - Q3 (N3 - Desenvolvimento)
A3: Kendall | B3: G/G/1/5
A4: Servidores (C) | B4: =Parâmetros!$E$7 -> 1
A5: Capacidade (K) | B5: =Parâmetros!$F$7 -> 5
A6: MU (clientes/h) | B6: =Parâmetros!$J$7 -> 1.3333333
A7: Tempo global (min) | B7: 146269.72
A8: Perdas | B8: 79
A10: i | B10: Tempo acumulado (min) | C10: Probabilidade | D10: N (clientes) | E10: D (cl/h) | F10: U
A11: 0 | B11: 23583.818 | C11: =B11/$B$7 -> 0.16123513 | D11: =C11*A11 -> 0 | E11: =C11*MIN(A11,$B$4)*$B$6 -> 0 | F11: =C11*MIN(A11,$B$4)/$B$4 -> 0
A12: 1 | B12: 41758.01 | C12: =B12/$B$7 -> 0.28548636 | D12: =C12*A12 -> 0.28548636 | E12: =C12*MIN(A12,$B$4)*$B$6 -> 0.38064848 | F12: =C12*MIN(A12,$B$4)/$B$4 -> 0.28548636
A13: 2 | B13: 33814.23 | C13: =B13/$B$7 -> 0.23117724 | D13: =C13*A13 -> 0.46235448 | E13: =C13*MIN(A13,$B$4)*$B$6 -> 0.30823632 | F13: =C13*MIN(A13,$B$4)/$B$4 -> 0.23117724
A14: 3 | B14: 23065.267 | C14: =B14/$B$7 -> 0.15768997 | D14: =C14*A14 -> 0.4730699 | E14: =C14*MIN(A14,$B$4)*$B$6 -> 0.21025329 | F14: =C14*MIN(A14,$B$4)/$B$4 -> 0.15768997
A15: 4 | B15: 17509.397 | C15: =B15/$B$7 -> 0.11970623 | D15: =C15*A15 -> 0.47882493 | E15: =C15*MIN(A15,$B$4)*$B$6 -> 0.15960831 | F15: =C15*MIN(A15,$B$4)/$B$4 -> 0.11970623
A16: 5 | B16: 6538.9973 | C16: =B16/$B$7 -> 0.044705065 | D16: =C16*A16 -> 0.22352533 | E16: =C16*MIN(A16,$B$4)*$B$6 -> 0.059606754 | F16: =C16*MIN(A16,$B$4)/$B$4 -> 0.044705065
A17: Total | B17: =SUM(B11:B16) -> 146269.72 | C17: =SUM(C11:C16) -> 1 | D17: =SUM(D11:D16) -> 1.923261 | E17: =SUM(E11:E16) -> 1.1183532 | F17: =SUM(F11:F16) -> 0.83876487
A19: W (horas) = N / D | B19: =D17/E17 -> 1.719726
A20: W (minutos) | B20: =B19*60 -> 103.18356
A22: Soma dos tempos = tempo global? | B22: =IF(ABS(B17-B7)<0.001,"OK","ERRO") -> OK

Sheet Melhorado_Q1
A1: Melhorado - Q1 (N1 - Triagem)
A3: Kendall | B3: G/G/2/∞
A4: Servidores (C) | B4: =Parâmetros!$E$9 -> 2
A5: Capacidade (K) | B5: =Parâmetros!$F$9 -> ∞
A6: MU (clientes/h) | B6: =Parâmetros!$J$9 -> 7.5
A7: Tempo global (min) | B7: 154191.66
A8: Perdas | B8: 0
A10: i | B10: Tempo acumulado (min) | C10: Probabilidade | D10: N (clientes) | E10: D (cl/h) | F10: U
A11: 0 | B11: 1939.0686 | C11: =B11/$B$7 -> 0.012575703 | D11: =C11*A11 -> 0 | E11: =C11*MIN(A11,$B$4)*$B$6 -> 0 | F11: =C11*MIN(A11,$B$4)/$B$4 -> 0
A12: 1 | B12: 92461.17 | C12: =B12/$B$7 -> 0.5996509 | D12: =C12*A12 -> 0.5996509 | E12: =C12*MIN(A12,$B$4)*$B$6 -> 4.4973818 | F12: =C12*MIN(A12,$B$4)/$B$4 -> 0.29982545
A13: 2 | B13: 56785.052 | C13: =B13/$B$7 -> 0.36827576 | D13: =C13*A13 -> 0.73655152 | E13: =C13*MIN(A13,$B$4)*$B$6 -> 5.5241364 | F13: =C13*MIN(A13,$B$4)/$B$4 -> 0.36827576
A14: 3 | B14: 2977.1115 | C14: =B14/$B$7 -> 0.019307863 | D14: =C14*A14 -> 0.05792359 | E14: =C14*MIN(A14,$B$4)*$B$6 -> 0.28961795 | F14: =C14*MIN(A14,$B$4)/$B$4 -> 0.019307863
A15: 4 | B15: 29.260686 | C15: =B15/$B$7 -> 0.00018976828 | D15: =C15*A15 -> 0.00075907311 | E15: =C15*MIN(A15,$B$4)*$B$6 -> 0.0028465242 | F15: =C15*MIN(A15,$B$4)/$B$4 -> 0.00018976828
A16: Total | B16: =SUM(B11:B15) -> 154191.66 | C16: =SUM(C11:C15) -> 1 | D16: =SUM(D11:D15) -> 1.3948851 | E16: =SUM(E11:E15) -> 10.313983 | F16: =SUM(F11:F15) -> 0.68759884
A18: W (horas) = N / D | B18: =D16/E16 -> 0.13524214
A19: W (minutos) | B19: =B18*60 -> 8.1145284
A21: Soma dos tempos = tempo global? | B21: =IF(ABS(B16-B7)<0.001,"OK","ERRO") -> OK

Sheet Melhorado_Q2
A1: Melhorado - Q2 (N2 - Especialista)
A3: Kendall | B3: G/G/2/10
A4: Servidores (C) | B4: =Parâmetros!$E$10 -> 2
A5: Capacidade (K) | B5: =Parâmetros!$F$10 -> 10
A6: MU (clientes/h) | B6: =Parâmetros!$J$10 -> 2
A7: Tempo global (min) | B7: 154191.66
A8: Perdas | B8: 19
A10: i | B10: Tempo acumulado (min) | C10: Probabilidade | D10: N (clientes) | E10: D (cl/h) | F10: U
A11: 0 | B11: 13755.763 | C11: =B11/$B$7 -> 0.089212105 | D11: =C11*A11 -> 0 | E11: =C11*MIN(A11,$B$4)*$B$6 -> 0 | F11: =C11*MIN(A11,$B$4)/$B$4 -> 0
A12: 1 | B12: 34838.953 | C12: =B12/$B$7 -> 0.22594576 | D12: =C12*A12 -> 0.22594576 | E12: =C12*MIN(A12,$B$4)*$B$6 -> 0.45189153 | F12: =C12*MIN(A12,$B$4)/$B$4 -> 0.11297288
A13: 2 | B13: 37189.485 | C13: =B13/$B$7 -> 0.24118999 | D13: =C13*A13 -> 0.48237997 | E13: =C13*MIN(A13,$B$4)*$B$6 -> 0.96475995 | F13: =C13*MIN(A13,$B$4)/$B$4 -> 0.24118999
A14: 3 | B14: 28872.329 | C14: =B14/$B$7 -> 0.18724961 | D14: =C14*A14 -> 0.56174883 | E14: =C14*MIN(A14,$B$4)*$B$6 -> 0.74899844 | F14: =C14*MIN(A14,$B$4)/$B$4 -> 0.18724961
A15: 4 | B15: 17039.044 | C15: =B15/$B$7 -> 0.11050561 | D15: =C15*A15 -> 0.44202245 | E15: =C15*MIN(A15,$B$4)*$B$6 -> 0.44202245 | F15: =C15*MIN(A15,$B$4)/$B$4 -> 0.11050561
A16: 5 | B16: 9475.6558 | C16: =B16/$B$7 -> 0.061453749 | D16: =C16*A16 -> 0.30726875 | E16: =C16*MIN(A16,$B$4)*$B$6 -> 0.245815 | F16: =C16*MIN(A16,$B$4)/$B$4 -> 0.061453749
A17: 6 | B17: 5719.8034 | C17: =B17/$B$7 -> 0.037095413 | D17: =C17*A17 -> 0.22257248 | E17: =C17*MIN(A17,$B$4)*$B$6 -> 0.14838165 | F17: =C17*MIN(A17,$B$4)/$B$4 -> 0.037095413
A18: 7 | B18: 3614.8646 | C18: =B18/$B$7 -> 0.023443969 | D18: =C18*A18 -> 0.16410778 | E18: =C18*MIN(A18,$B$4)*$B$6 -> 0.093775877 | F18: =C18*MIN(A18,$B$4)/$B$4 -> 0.023443969
A19: 8 | B19: 2269.195 | C19: =B19/$B$7 -> 0.014716717 | D19: =C19*A19 -> 0.11773373 | E19: =C19*MIN(A19,$B$4)*$B$6 -> 0.058866866 | F19: =C19*MIN(A19,$B$4)/$B$4 -> 0.014716717
A20: 9 | B20: 1076.9446 | C20: =B20/$B$7 -> 0.0069844543 | D20: =C20*A20 -> 0.062860089 | E20: =C20*MIN(A20,$B$4)*$B$6 -> 0.027937817 | F20: =C20*MIN(A20,$B$4)/$B$4 -> 0.0069844543
A21: 10 | B21: 339.62546 | C21: =B21/$B$7 -> 0.0022026188 | D21: =C21*A21 -> 0.022026188 | E21: =C21*MIN(A21,$B$4)*$B$6 -> 0.0088104752 | F21: =C21*MIN(A21,$B$4)/$B$4 -> 0.0022026188
A22: Total | B22: =SUM(B11:B21) -> 154191.66 | C22: =SUM(C11:C21) -> 1 | D22: =SUM(D11:D21) -> 2.608666 | E22: =SUM(E11:E21) -> 3.1912601 | F22: =SUM(F11:F21) -> 0.79781501
A24: W (horas) = N / D | B24: =D22/E22 -> 0.81744076
A25: W (minutos) | B25: =B24*60 -> 49.046446
A27: Soma dos tempos = tempo global? | B27: =IF(ABS(B22-B7)<0.001,"OK","ERRO") -> OK

Sheet Melhorado_Q3
A1: Melhorado - Q3 (N3 - Desenvolvimento)
A3: Kendall | B3: G/G/1/5
A4: Servidores (C) | B4: =Parâmetros!$E$11 -> 1
A5: Capacidade (K) | B5: =Parâmetros!$F$11 -> 5
A6: MU (clientes/h) | B6: =Parâmetros!$J$11 -> 1.3333333
A7: Tempo global (min) | B7: 154191.66
A8: Perdas | B8: 15
A10: i | B10: Tempo acumulado (min) | C10: Probabilidade | D10: N (clientes) | E10: D (cl/h) | F10: U
A11: 0 | B11: 43496.914 | C11: =B11/$B$7 -> 0.28209641 | D11: =C11*A11 -> 0 | E11: =C11*MIN(A11,$B$4)*$B$6 -> 0 | F11: =C11*MIN(A11,$B$4)/$B$4 -> 0
A12: 1 | B12: 53992.889 | C12: =B12/$B$7 -> 0.35016737 | D12: =C12*A12 -> 0.35016737 | E12: =C12*MIN(A12,$B$4)*$B$6 -> 0.46688983 | F12: =C12*MIN(A12,$B$4)/$B$4 -> 0.35016737
A13: 2 | B13: 33062.391 | C13: =B13/$B$7 -> 0.21442399 | D13: =C13*A13 -> 0.42884797 | E13: =C13*MIN(A13,$B$4)*$B$6 -> 0.28589865 | F13: =C13*MIN(A13,$B$4)/$B$4 -> 0.21442399
A14: 3 | B14: 15228.679 | C14: =B14/$B$7 -> 0.098764605 | D14: =C14*A14 -> 0.29629381 | E14: =C14*MIN(A14,$B$4)*$B$6 -> 0.13168614 | F14: =C14*MIN(A14,$B$4)/$B$4 -> 0.098764605
A15: 4 | B15: 6674.1249 | C15: =B15/$B$7 -> 0.043284603 | D15: =C15*A15 -> 0.17313841 | E15: =C15*MIN(A15,$B$4)*$B$6 -> 0.057712804 | F15: =C15*MIN(A15,$B$4)/$B$4 -> 0.043284603
A16: 5 | B16: 1736.665 | C16: =B16/$B$7 -> 0.011263028 | D16: =C16*A16 -> 0.056315139 | E16: =C16*MIN(A16,$B$4)*$B$6 -> 0.01501737 | F16: =C16*MIN(A16,$B$4)/$B$4 -> 0.011263028
A17: Total | B17: =SUM(B11:B16) -> 154191.66 | C17: =SUM(C11:C16) -> 1 | D17: =SUM(D11:D16) -> 1.3047627 | E17: =SUM(E11:E16) -> 0.95720479 | F17: =SUM(F11:F16) -> 0.71790359
A19: W (horas) = N / D | B19: =D17/E17 -> 1.3630967
A20: W (minutos) | B20: =B19*60 -> 81.785803
A22: Soma dos tempos = tempo global? | B22: =IF(ABS(B17-B7)<0.001,"OK","ERRO") -> OK

Sheet Sementes
A1: Mesmos modelos com 5 sementes (100.000 aleatórios cada)
A2: Azul = resultado de cada simulação. A média e o desvio padrão são fórmulas. Mostra que os ganhos da melhoria não dependem da semente escolhida.
A4: Modelo | B4: Fila | C4: Semente | D4: Perdas | E4: N | F4: D (cl/h) | G4: U | H4: W (min)
A5: Atual | B5: Q1 | C5: 1 | D5: 0 | E5: 1.4156813 | F5: 10.417063 | G5: 0.69447087 | H5: 8.1540137
A6: Atual | B6: Q1 | C6: 2 | D6: 0 | E6: 1.4047812 | F6: 10.355764 | G6: 0.69038429 | H6: 8.1391259
A7: Atual | B7: Q1 | C7: 3 | D7: 0 | E7: 1.4111248 | F7: 10.386947 | G7: 0.69246313 | H7: 8.1513355
A8: Atual | B8: Q1 | C8: 4 | D8: 0 | E8: 1.4100515 | F8: 10.388264 | G8: 0.6925509 | H8: 8.1441035
A9: Atual | B9: Q1 | C9: 5 | D9: 0 | E9: 1.4150604 | F9: 10.41804 | G9: 0.69453602 | H9: 8.1496731
A10: Atual | B10: Q1 | C10: Média | D10: =AVERAGE(D5:D9) -> 0 | E10: =AVERAGE(E5:E9) -> 1.4113398 | F10: =AVERAGE(F5:F9) -> 10.393216 | G10: =AVERAGE(G5:G9) -> 0.69288104 | H10: =AVERAGE(H5:H9) -> 8.1476503
A11: Atual | B11: Q1 | C11: Desvio padrão | D11: =STDEV(D5:D9) -> 0 | E11: =STDEV(E5:E9) -> 0.0043992139 | F11: =STDEV(F5:F9) -> 0.02574578 | G11: =STDEV(G5:G9) -> 0.0017163853 | H11: =STDEV(H5:H9) -> 0.0059877202
A13: Atual | B13: Q2 | C13: 1 | D13: 2057 | E13: 8.1739699 | F13: 3.991643 | G13: 0.99791074 | H13: 122.86625
A14: Atual | B14: Q2 | C14: 2 | D14: 2322 | E14: 8.3661703 | F14: 3.9979698 | G14: 0.99949245 | H14: 125.55628
A15: Atual | B15: Q2 | C15: 3 | D15: 2281 | E15: 8.432279 | F15: 3.9985601 | G15: 0.99964003 | H15: 126.52973
A16: Atual | B16: Q2 | C16: 4 | D16: 2405 | E16: 8.475945 | F16: 3.9965693 | G16: 0.99914233 | H16: 127.24831
A17: Atual | B17: Q2 | C17: 5 | D17: 2182 | E17: 8.245491 | F17: 3.9892637 | G17: 0.99731592 | H17: 124.01523
A18: Atual | B18: Q2 | C18: Média | D18: =AVERAGE(D13:D17) -> 2249.4 | E18: =AVERAGE(E13:E17) -> 8.3387711 | F18: =AVERAGE(F13:F17) -> 3.9948012 | G18: =AVERAGE(G13:G17) -> 0.9987003 | H18: =AVERAGE(H13:H17) -> 125.24316
A19: Atual | B19: Q2 | C19: Desvio padrão | D19: =STDEV(D13:D17) -> 134.20246 | E19: =STDEV(E13:E17) -> 0.12666073 | F19: =STDEV(F13:F17) -> 0.0041211138 | G19: =STDEV(G13:G17) -> 0.0010302784 | H19: =STDEV(H13:H17) -> 1.798018
A21: Atual | B21: Q3 | C21: 1 | D21: 79 | E21: 1.923261 | F21: 1.1183532 | G21: 0.83876487 | H21: 103.18356
A22: Atual | B22: Q3 | C22: 2 | D22: 132 | E22: 2.1949683 | F22: 1.1699879 | G22: 0.87749094 | H22: 112.56364
A23: Atual | B23: Q3 | C23: 3 | D23: 103 | E23: 2.169191 | F23: 1.1569508 | G23: 0.86771312 | H23: 112.49524
A24: Atual | B24: Q3 | C24: 4 | D24: 163 | E24: 2.1829956 | F24: 1.1587885 | G24: 0.86909141 | H24: 113.03161
A25: Atual | B25: Q3 | C25: 5 | D25: 146 | E25: 2.1899903 | F25: 1.1626332 | G25: 0.8719749 | H25: 113.01881
A26: Atual | B26: Q3 | C26: Média | D26: =AVERAGE(D21:D25) -> 124.6 | E26: =AVERAGE(E21:E25) -> 2.1320812 | F26: =AVERAGE(F21:F25) -> 1.1533427 | G26: =AVERAGE(G21:G25) -> 0.86500705 | H26: =AVERAGE(H21:H25) -> 110.85857
A27: Atual | B27: Q3 | C27: Desvio padrão | D27: =STDEV(D21:D25) -> 33.664521 | E27: =STDEV(E21:E25) -> 0.11713618 | F27: =STDEV(F21:F25) -> 0.020188617 | G27: =STDEV(G21:G25) -> 0.015141463 | H27: =STDEV(H21:H25) -> 4.2976867
A29: Melhorado | B29: Q1 | C29: 1 | D29: 0 | E29: 1.3948851 | F29: 10.313983 | G29: 0.68759884 | H29: 8.1145284
A30: Melhorado | B30: Q1 | C30: 2 | D30: 0 | E30: 1.4065612 | F30: 10.363048 | G30: 0.69086989 | H30: 8.1437111
A31: Melhorado | B31: Q1 | C31: 3 | D31: 0 | E31: 1.3985404 | F31: 10.328549 | G31: 0.68856994 | H31: 8.1243188
A32: Melhorado | B32: Q1 | C32: 4 | D32: 0 | E32: 1.408247 | F32: 10.37297 | G32: 0.69153135 | H32: 8.1456726
A33: Melhorado | B33: Q1 | C33: 5 | D33: 0 | E33: 1.395391 | F33: 10.308568 | G33: 0.68723787 | H33: 8.1217352
A34: Melhorado | B34: Q1 | C34: Média | D34: =AVERAGE(D29:D33) -> 0 | E34: =AVERAGE(E29:E33) -> 1.4007249 | F34: =AVERAGE(F29:F33) -> 10.337424 | G34: =AVERAGE(G29:G33) -> 0.68916158 | H34: =AVERAGE(H29:H33) -> 8.1299932
A35: Melhorado | B35: Q1 | C35: Desvio padrão | D35: =STDEV(D29:D33) -> 0 | E35: =STDEV(E29:E33) -> 0.0062843071 | F35: =STDEV(F29:F33) -> 0.029073484 | G35: =STDEV(G29:G33) -> 0.0019382322 | H35: =STDEV(H29:H33) -> 0.013906625
A37: Melhorado | B37: Q2 | C37: 1 | D37: 19 | E37: 2.608666 | F37: 3.1912601 | G37: 0.79781501 | H37: 49.046446
A38: Melhorado | B38: Q2 | C38: 2 | D38: 25 | E38: 2.825345 | F38: 3.3002683 | G38: 0.82506707 | H38: 51.365733
A39: Melhorado | B39: Q2 | C39: 3 | D39: 33 | E39: 2.8535925 | F39: 3.2846726 | G39: 0.82116816 | H39: 52.125605
A40: Melhorado | B40: Q2 | C40: 4 | D40: 43 | E40: 3.0938701 | F40: 3.3396454 | G40: 0.83491135 | H40: 55.584406
A41: Melhorado | B41: Q2 | C41: 5 | D41: 30 | E41: 2.8290271 | F41: 3.2977755 | G41: 0.82444389 | H41: 51.471552
A42: Melhorado | B42: Q2 | C42: Média | D42: =AVERAGE(D37:D41) -> 30 | E42: =AVERAGE(E37:E41) -> 2.8421001 | F42: =AVERAGE(F37:F41) -> 3.2827244 | G42: =AVERAGE(G37:G41) -> 0.8206811 | H42: =AVERAGE(H37:H41) -> 51.918748
A43: Melhorado | B43: Q2 | C43: Desvio padrão | D43: =STDEV(D37:D41) -> 9 | E43: =STDEV(E37:E41) -> 0.17209249 | F43: =STDEV(F37:F41) -> 0.055099561 | G43: =STDEV(G37:G41) -> 0.01377489 | H43: =STDEV(H37:H41) -> 2.357741
A45: Melhorado | B45: Q3 | C45: 1 | D45: 15 | E45: 1.3047627 | F45: 0.95720479 | G45: 0.71790359 | H45: 81.785803
A46: Melhorado | B46: Q3 | C46: 2 | D46: 32 | E46: 1.3751723 | F46: 0.97536887 | G46: 0.73152665 | H46: 84.593986
...
